from django.test import TestCase
from django.contrib.auth.models import User
from django.core.exceptions import ValidationError

from .models import Organization, validate_twitter_name

class DirectoryTests(TestCase):
    def test_user_membership_is_created_on_save(self):
        user = User(username='foo')
        user.save()
        self.assertTrue(user.membership)
        self.assertTrue(user.membership.is_listed)
        self.assertFalse(user.membership.organization)

    def test_validate_twitter_name_rejects_invalid_names(self):
        self.assertRaises(ValidationError, validate_twitter_name, '$')
        self.assertRaises(ValidationError, validate_twitter_name,
                          'reallyreallyreallyreallylongusername')

    def test_validate_twitter_name_accepts_valid_names(self):
        validate_twitter_name('toolness')
        validate_twitter_name('t')
        validate_twitter_name('super_burger')
